WARNING:absl:No GPU/TPU found, falling back to CPU. (Set TF_CPP_MIN_LOG_LEVEL=0 and rerun for more info.)
/home/liang/miniconda3/lib/python3.9/site-packages/torch/utils/data/dataloader.py:563: UserWarning: This DataLoader will create 8 worker processes in total. Our suggested max number of worker in current system is 4, which is smaller than what this DataLoader is going to create. Please be aware that excessive worker creation might get DataLoader running slow or even freeze, lower the worker number to avoid potential slowness/freeze if necessary.
  warnings.warn(_create_warning_msg(
Traceback (most recent call last):
  File "/home/liang/文档/Coding/Machine Learning/MetaAF/zoo/aec/aec.py", line 558, in <module>
    outer_learned, losses = system.train(
  File "/home/liang/miniconda3/lib/python3.9/site-packages/metaaf/meta.py", line 368, in train
    self.outer_learnable = self.init_outer_learnable(subkey)
  File "/home/liang/miniconda3/lib/python3.9/site-packages/metaaf/meta.py", line 284, in init_outer_learnable
    batch = next(iter(self.train_loader))
  File "/home/liang/miniconda3/lib/python3.9/site-packages/torch/utils/data/dataloader.py", line 681, in __next__
    data = self._next_data()
  File "/home/liang/miniconda3/lib/python3.9/site-packages/torch/utils/data/dataloader.py", line 1376, in _next_data
    return self._process_data(data)
  File "/home/liang/miniconda3/lib/python3.9/site-packages/torch/utils/data/dataloader.py", line 1402, in _process_data
    data.reraise()
  File "/home/liang/miniconda3/lib/python3.9/site-packages/torch/_utils.py", line 461, in reraise
    raise exception
RuntimeError: Caught RuntimeError in DataLoader worker process 0.
Original Traceback (most recent call last):
  File "/home/liang/miniconda3/lib/python3.9/site-packages/torch/utils/data/_utils/worker.py", line 302, in _worker_loop
    data = fetcher.fetch(index)
  File "/home/liang/miniconda3/lib/python3.9/site-packages/torch/utils/data/_utils/fetch.py", line 49, in fetch
    data = [self.dataset[idx] for idx in possibly_batched_index]
  File "/home/liang/miniconda3/lib/python3.9/site-packages/torch/utils/data/_utils/fetch.py", line 49, in <listcomp>
    data = [self.dataset[idx] for idx in possibly_batched_index]
  File "/home/liang/文档/Coding/Machine Learning/MetaAF/zoo/aec/aec.py", line 173, in __getitem__
    data_dict = self.load_from_idx(idx)
  File "/home/liang/文档/Coding/Machine Learning/MetaAF/zoo/aec/aec.py", line 127, in load_from_idx
    d, sr = sf.read(
  File "/home/liang/miniconda3/lib/python3.9/site-packages/soundfile.py", line 256, in read
    with SoundFile(file, 'r', samplerate, channels,
  File "/home/liang/miniconda3/lib/python3.9/site-packages/soundfile.py", line 629, in __init__
    self._file = self._open(file, mode_int, closefd)
  File "/home/liang/miniconda3/lib/python3.9/site-packages/soundfile.py", line 1183, in _open
    _error_check(_snd.sf_error(file_ptr),
  File "/home/liang/miniconda3/lib/python3.9/site-packages/soundfile.py", line 1357, in _error_check
    raise RuntimeError(prefix + _ffi.string(err_str).decode('utf-8', 'replace'))
RuntimeError: Error opening '/home/liang/DataSet/AEC-Challenge/datasets/synthetic/nearend_mic_signal/nearend_mic_fileid_5131.wav': Format not recognised.